<?xml version="1.0"?>
<robot name="my_robot">

  <link name="base_link">
    <visual>
      <geometry>
        <cylinder length="0.02" radius="0.15"/>
      </geometry>
      <origin rpy="0 0 0" xyz="0 0 0"/>
    </visual>
  </link>

  <link name="right_wheel">
    <visual>
      <geometry>
        <cylinder length="0.02" radius="0.04"/>
      </geometry>
      <origin rpy="1.57 0 0" xyz="0 0 0"/>
    </visual>
  </link>

  <link name="left_wheel">
    <visual>
      <geometry>
        <cylinder length="0.02" radius="0.04"/>
      </geometry>
      <origin rpy="1.57 0 0" xyz="0 0 0"/>
    </visual>
  </link>

  <link name="caster_front_wheel">
    <visual>
      <geometry>
        <sphere radius="0.025"/>
      </geometry>
      <origin rpy="1.57 0 0" xyz="0 0.02 0"/>
    </visual>
  </link>

  <link name="caster_back_wheel">
    <visual>
      <geometry>
        <sphere radius="0.025"/>
      </geometry>
      <origin rpy="1.57 0 0" xyz="0.02 0.02 0"/>
    </visual>
  </link>
  
  <joint name="right_wheel_joint" type="continuous">
    <parent link="base_link"/>
    <child link="right_wheel"/>
    <origin rpy="0 0 0" xyz="0 0.15 0"/>
    <axis rpy="0 0 0" xyz="0 1 0"/>
    <limit effort="100" velocity="100"/>
  </joint>

  <joint name="left_wheel_joint" type="continuous">
    <parent link="base_link"/>
    <child link="left_wheel"/>
    <origin rpy="0 0 0" xyz="0 -0.15 0"/>
    <axis rpy="0 0 0" xyz="0 1 0"/>
    <limit effort="100" velocity="100"/>
  </joint>

  <joint name="caster_front_wheel_joint" type="fixed">
    <parent link="base_link"/>
    <child link="caster_front_wheel"/>
    <origin rpy="-1.57 0 0" xyz="0.115 0 0.007"/>
  </joint>

  <joint name="caster_back_wheel_joint" type="fixed">
    <parent link="base_link"/>
    <child link="caster_back_wheel"/>
    <origin rpy="-1.57 0 0" xyz="-0.135 0 0.009"/>
  </joint>
</robot>
